{
    "registryname": "metallurgic_fabricator",
    "localizedname": "Metallurgic Fabricator",
    "color": "9970BA",
    "requires-blueprint": true,
    "parts": [
        {
            "x": -1,
            "y": 0,
            "z": 0,
            "elements": [
                "contenttweaker:titanium_machine_casing@0"
            ]
        },
        {
            "x": -1,
            "y": 0,
            "z": 1,
            "elements": [
                "metalfabcasing"
            ]
        },
        {
            "x": 0,
            "y": 2,
            "z": 2,
            "elements": [
                "metalfabcasing"
            ]
        },
        {
            "x": 1,
            "y": 2,
            "z": 1,
            "elements": [
                "metalfabcasing"
            ]
        },
        {
            "x": 0,
            "y": 0,
            "z": 1,
            "elements": [
                "thermalfoundation:storage@6"
            ]
        },
        {
            "x": 1,
            "y": 0,
            "z": 0,
            "elements": [
                "contenttweaker:titanium_machine_casing@0"
            ]
        },
        {
            "x": -1,
            "y": 0,
            "z": 2,
            "elements": [
                "contenttweaker:titanium_machine_casing@0"
            ]
        },
        {
            "x": 1,
            "y": 2,
            "z": 2,
            "elements": [
                "contenttweaker:titanium_machine_casing@0"
            ]
        },
        {
            "x": 1,
            "y": 0,
            "z": 1,
            "elements": [
                "metalfabcasing"
            ]
        },
        {
            "x": 0,
            "y": 0,
            "z": 2,
            "elements": [
                "metalfabcasing"
            ]
        },
        {
            "x": 1,
            "y": 0,
            "z": 2,
            "elements": [
                "contenttweaker:titanium_machine_casing@0"
            ]
        },
        {
            "x": -1,
            "y": 3,
            "z": 0,
            "elements": [
                "contenttweaker:titanium_machine_casing@0"
            ]
        },
        {
            "x": 0,
            "y": 3,
            "z": 0,
            "elements": [
                "contenttweaker:titanium_machine_casing@0"
            ]
        },
        {
            "x": 1,
            "y": -1,
            "z": 0,
            "elements": [
                "contenttweaker:titanium_machine_casing@0"
            ]
        },
        {
            "x": -1,
            "y": 3,
            "z": 1,
            "elements": [
                "contenttweaker:titanium_machine_casing@0"
            ]
        },
        {
            "x": 0,
            "y": 3,
            "z": 1,
            "elements": [
                "modularmachinery:blockcasing@1"
            ]
        },
        {
            "x": 1,
            "y": 3,
            "z": 0,
            "elements": [
                "contenttweaker:titanium_machine_casing@0"
            ]
        },
        {
            "x": 0,
            "y": -1,
            "z": 0,
            "elements": [
                "contenttweaker:titanium_machine_casing@0"
            ]
        },
        {
            "x": -1,
            "y": 1,
            "z": 0,
            "elements": [
                "contenttweaker:titanium_machine_casing@0"
            ]
        },
        {
            "x": -1,
            "y": 3,
            "z": 2,
            "elements": [
                "contenttweaker:titanium_machine_casing@0"
            ]
        },
        {
            "x": 0,
            "y": 3,
            "z": 2,
            "elements": [
                "contenttweaker:titanium_machine_casing@0"
            ]
        },
        {
            "x": 1,
            "y": 3,
            "z": 1,
            "elements": [
                "contenttweaker:titanium_machine_casing@0"
            ]
        },
        {
            "x": -1,
            "y": -1,
            "z": 0,
            "elements": [
                "contenttweaker:titanium_machine_casing@0"
            ]
        },
        {
            "x": 0,
            "y": 1,
            "z": 0,
            "elements": [
                "contenttweaker:titanium_machine_casing@0"
            ]
        },
        {
            "x": -1,
            "y": 1,
            "z": 1,
            "elements": [
                "contenttweaker:titanium_machine_casing@0"
            ]
        },
        {
            "x": 1,
            "y": 3,
            "z": 2,
            "elements": [
                "contenttweaker:titanium_machine_casing@0"
            ]
        },
        {
            "x": 0,
            "y": 1,
            "z": 1,
            "elements": [
                "thermalfoundation:storage@6"
            ]
        },
        {
            "x": 1,
            "y": 1,
            "z": 0,
            "elements": [
                "contenttweaker:titanium_machine_casing@0"
            ]
        },
        {
            "x": -1,
            "y": 1,
            "z": 2,
            "elements": [
                "contenttweaker:titanium_machine_casing@0"
            ]
        },
        {
            "x": 0,
            "y": 1,
            "z": 2,
            "elements": [
                "contenttweaker:titanium_machine_casing@0"
            ]
        },
        {
            "x": 1,
            "y": 1,
            "z": 1,
            "elements": [
                "contenttweaker:titanium_machine_casing@0"
            ]
        },
        {
            "x": -1,
            "y": -1,
            "z": 1,
            "elements": [
                "contenttweaker:titanium_machine_casing@0"
            ]
        },
        {
            "x": 1,
            "y": 1,
            "z": 2,
            "elements": [
                "contenttweaker:titanium_machine_casing@0"
            ]
        },
        {
            "x": 0,
            "y": -1,
            "z": 1,
            "elements": [
                "modularmachinery:blockcasing@2"
            ]
        },
        {
            "x": -1,
            "y": -1,
            "z": 2,
            "elements": [
                "contenttweaker:titanium_machine_casing@0"
            ]
        },
        {
            "x": 0,
            "y": -1,
            "z": 2,
            "elements": [
                "contenttweaker:titanium_machine_casing@0"
            ]
        },
        {
            "x": 1,
            "y": -1,
            "z": 1,
            "elements": [
                "contenttweaker:titanium_machine_casing@0"
            ]
        },
        {
            "x": 1,
            "y": -1,
            "z": 2,
            "elements": [
                "contenttweaker:titanium_machine_casing@0"
            ]
        },
        {
            "x": -1,
            "y": 2,
            "z": 0,
            "elements": [
                "contenttweaker:titanium_machine_casing@0"
            ]
        },
        {
            "x": -1,
            "y": 2,
            "z": 1,
            "elements": [
                "metalfabcasing"
            ]
        },
        {
            "x": 0,
            "y": 2,
            "z": 0,
            "elements": [
                "metalfabcasing"
            ]
        },
        {
            "x": -1,
            "y": 2,
            "z": 2,
            "elements": [
                "contenttweaker:titanium_machine_casing@0"
            ]
        },
        {
            "x": 0,
            "y": 2,
            "z": 1,
            "elements": [
                "thermalfoundation:storage@6"
            ]
        },
        {
            "x": 1,
            "y": 2,
            "z": 0,
            "elements": [
                "contenttweaker:titanium_machine_casing@0"
            ]
        }
    ]
}